<?xml version='1.0'?>
<sdf version="1.4">
  <model name="EspressoFrameHead">
    <link name="body_link">
      <pose>0 0 0 0 0 0</pose>
      <inertial>
        <pose>-0.01 0 0.015 0 0 0</pose>
        <mass>0.1</mass>
        <inertia>
          <ixx>0.0000108</ixx>
          <ixy>0.0</ixy>
          <ixz>0.0</ixz>
          <iyy>0.0000208</iyy>
          <iyz>0.0</iyz>
          <izz>0.0000167</izz>
        </inertia>
      </inertial>
      <collision name="collision">
        <pose>-0.01 0 0.015 0 0 0</pose>
        <geometry>
          <box>
            <size>0.04 0.02 0.03</size>
          </box>
        </geometry>
      </collision>
      <visual name="visual">
        <pose>-0.01 0 0.015 0 0 0</pose>
        <geometry>
          <box>
            <size>0.04 0.02 0.03</size>
          </box>
        </geometry>
        <material>
          <script>
            <uri>file://media/materials/scripts/gazebo.material</uri>
            <name>Gazebo/Grey</name>
          </script>
        </material>
      </visual>
    </link>

    <joint name='yaw_joint' type='revolute'>
      <parent>body_link</parent>
      <child>yaw_link</child>
      <pose>0 0 0 0 0 0</pose>
      <axis>
        <use_parent_model_frame>true</use_parent_model_frame>
        <xyz>0 0 1</xyz>
        <limit>
          <lower>-1.5707</lower>
          <upper>1.5707</upper>
          <effort>1.0</effort>
          <velocity>3.0</velocity>
        </limit>
      </axis>
    </joint>

    <link name="yaw_link">
      <pose>0 0 -0.05 0 0 0</pose>
      <inertial>
        <mass>0.1</mass>
        <inertia>
          <ixx>0.0000167</ixx>
          <ixy>0.0</ixy>
          <ixz>0.0</ixz>
          <iyy>0.0000108</iyy>
          <iyz>0.0</iyz>
          <izz>0.0000208</izz>
        </inertia>
      </inertial>
      <collision name="collision">
        <pose>-0.01 0 0 0 0 0</pose>
        <geometry>
          <box>
            <size>0.04 0.03 0.02</size>
          </box>
        </geometry>
      </collision>
      <visual name="visual1">
        <pose>-0.01 0 0 0 0 0</pose>
        <geometry>
          <box>
            <size>0.04 0.03 0.02</size>
          </box>
        </geometry>
        <material>
          <script>
            <uri>file://media/materials/scripts/gazebo.material</uri>
            <name>Gazebo/Red</name>
          </script>
        </material>
      </visual>
    </link>

    <joint name='pitch_joint' type='revolute'>
      <parent>yaw_link</parent>
      <child>pitch_link</child>
      <pose>-0.04 0 0 0 0 0</pose>
      <axis>
        <use_parent_model_frame>true</use_parent_model_frame>
        <xyz>0 1 0</xyz>
        <limit>
          <lower>-1.5707</lower>
          <upper>1.5707</upper>
          <effort>1.0</effort>
          <velocity>3.0</velocity>
        </limit>
        <dynamics>
          <damping>0.0001</damping>
          <friction>0.0002</friction>
        </dynamics>
      </axis>
    </joint>

    <link name="pitch_link">
      <pose>0.04 0 -0.05 0 0 0</pose>
      <inertial>
        <pose>-0.04 0 0 0 0 0</pose>
        <mass>0.1</mass>
        <inertia>
          <ixx>0.000044</ixx>
          <ixy>0.0</ixy>
          <ixz>0.0</ixz>
          <iyy>0.000011</iyy>
          <iyz>0.0</iyz>
          <izz>0.000048</izz>
        </inertia>
      </inertial>
      <collision name="collision">
        <geometry>
          <box>
            <size>0.02 0.07 0.03</size>
          </box>
        </geometry>
      </collision>
      <visual name="visual1">
        <geometry>
          <box>
            <size>0.02 0.07 0.03</size>
          </box>
        </geometry>
        <material>
          <script>
            <uri>file://media/materials/scripts/gazebo.material</uri>
            <name>Gazebo/Red</name>
          </script>
        </material>
      </visual>
      <sensor type="camera" name="camera1">
        <visualize>true</visualize>
        <update_rate>10.0</update_rate>
        <camera name="head">
          <horizontal_fov>1.3</horizontal_fov>
          <image>
            <width>800</width>
            <height>600</height>
            <format>R8G8B8</format>
          </image>
          <clip>
            <near>0.02</near>
            <far>30</far>
          </clip>
          <noise>
            <type>gaussian</type>
            <mean>0.0</mean>
            <stddev>0.007</stddev>
          </noise>
        </camera>
        <plugin name="head_camera_controller" filename="libgazebo_ros_camera.so">
          <alwaysOn>true</alwaysOn>
          <updateRate>0.0</updateRate>
          <cameraName>head_camera</cameraName>
          <imageTopicName>/device/head_camera/image_raw</imageTopicName>
          <cameraInfoTopicName>/device/head_camera/camera_info</cameraInfoTopicName>
          <frameName>head_camera_optical_link</frameName>
          <hackBaseline>0.0</hackBaseline>
          <distortionK1>0.0</distortionK1>
          <distortionK2>0.0</distortionK2>
          <distortionK3>0.0</distortionK3>
          <distortionT1>0.0</distortionT1>
          <distortionT2>0.0</distortionT2>
        </plugin>
      </sensor>
    </link>

    <plugin name="feetech_turret_plugin" filename="libfeetech_turret_plugin.so">
    </plugin>
  </model>
</sdf>
