<?xml version='1.0'?>
<sdf version="1.4">
  <model name="EspressoFrameMove">
    <link name="body_link">
      <pose>0 0 0.072 0 0 0</pose>
      <inertial>
        <pose>-0.06 0 0 0 0 0</pose>
        <mass>4.0</mass>
        <inertia>
          <ixx>0.033</ixx>
          <ixy>0.0</ixy>
          <ixz>0.0</ixz>
          <iyy>0.033</iyy>
          <iyz>0.0</iyz>
          <izz>0.06</izz>
        </inertia>
      </inertial>
      <collision name="collision">
        <pose>-0.06 0 0 0 0 0</pose>
        <geometry>
          <box>
            <size>0.220 0.260 0.05</size>
          </box>
        </geometry>
      </collision>
      <visual name="visual">
        <pose>-0.06 0 0 0 0 0</pose>
        <geometry>
          <box>
            <size>0.220 0.260 0.05</size>
          </box>
        </geometry>
        <material>
          <script>
            <uri>file://media/materials/scripts/gazebo.material</uri>
            <name>Gazebo/Grey</name>
          </script>
        </material>
      </visual>

      <visual name="visual1">
        <pose>0 0 0.027 0 0 0</pose>
        <geometry>
          <cylinder>
            <radius>0.210</radius>
            <length>0.004</length>
          </cylinder>
        </geometry>
        <material>
          <script>
            <uri>file://media/materials/scripts/gazebo.material</uri>
            <name>Gazebo/White</name>
          </script>
        </material>
      </visual>
      <visual name="visual2">
        <pose>-0.210 0 0.027 0 0 0</pose>
        <geometry>
          <cylinder>
            <radius>0.085</radius>
            <length>0.004</length>
          </cylinder>
        </geometry>
        <material>
          <script>
            <uri>file://media/materials/scripts/gazebo.material</uri>
            <name>Gazebo/White</name>
          </script>
        </material>
      </visual>
      <visual name="visual3">
        <pose>0 0 -0.027 0 0 0</pose>
        <geometry>
          <cylinder>
            <radius>0.210</radius>
            <length>0.004</length>
          </cylinder>
        </geometry>
        <material>
          <script>
            <uri>file://media/materials/scripts/gazebo.material</uri>
            <name>Gazebo/White</name>
          </script>
        </material>
      </visual>
    </link>

    <joint name='left_wheel_joint' type='revolute'>
      <parent>body_link</parent>
      <child>left_wheel_link</child>
      <pose>0 0 0.072 0 0 0</pose>
      <axis>
        <use_parent_model_frame>true</use_parent_model_frame>
        <xyz>0 1 0</xyz>
      </axis>
    </joint>
    <link name="left_wheel_link">
      <pose>0 0.18 0.072 1.5707 0 0</pose>
      <inertial>
        <mass>0.1</mass>
        <inertia>
          <ixx>0.00013</ixx>
          <ixy>0.0</ixy>
          <ixz>0.0</ixz>
          <iyy>0.00013</iyy>
          <iyz>0.0</iyz>
          <izz>0.00026</izz>
        </inertia>
      </inertial>
      <collision name="collision">
        <geometry>
          <cylinder>
            <radius>0.072</radius>
            <length>0.01</length>
          </cylinder>
        </geometry>
        <surface>
          <contact>
            <ode>
              <kp>100000</kp>
              <kd>1</kd>
            </ode>
          </contact>
        </surface>
      </collision>
      <visual name="visual">
        <geometry>
          <cylinder>
            <radius>0.072</radius>
            <length>0.01</length>
          </cylinder>
        </geometry>
        <material>
          <script>
            <uri>file://media/materials/scripts/gazebo.material</uri>
            <name>Gazebo/Red</name>
          </script>
        </material>
      </visual>
    </link>

    <joint name='right_wheel_joint' type='revolute'>
      <parent>body_link</parent>
      <child>right_wheel_link</child>
      <pose>0 0 0.072 0 0 0</pose>
      <axis>
        <use_parent_model_frame>true</use_parent_model_frame>
        <xyz>0 1 0</xyz>
      </axis>
    </joint>
    <link name="right_wheel_link">
      <pose>0 -0.18 0.072 1.5707 0 0</pose>
      <inertial>
        <mass>0.1</mass>
        <inertia>
          <ixx>0.00013</ixx>
          <ixy>0.0</ixy>
          <ixz>0.0</ixz>
          <iyy>0.00013</iyy>
          <iyz>0.0</iyz>
          <izz>0.00026</izz>
        </inertia>
      </inertial>
      <collision name="collision">
        <geometry>
          <cylinder>
            <radius>0.072</radius>
            <length>0.01</length>
          </cylinder>
        </geometry>
        <surface>
          <contact>
            <ode>
              <kp>100000</kp>
              <kd>1</kd>
            </ode>
          </contact>
        </surface>
      </collision>
      <visual name="visual">
        <geometry>
          <cylinder>
            <radius>0.072</radius>
            <length>0.01</length>
          </cylinder>
        </geometry>
        <material>
          <script>
            <uri>file://media/materials/scripts/gazebo.material</uri>
            <name>Gazebo/Red</name>
          </script>
        </material>
      </visual>
    </link>

    <joint name='caster_joint' type='fixed'>
      <parent>body_link</parent>
      <child>caster_link</child>
      <pose>0 0 0 0 0 0</pose>
      <axis>
        <use_parent_model_frame>true</use_parent_model_frame>
        <xyz>0 1 0</xyz>
      </axis>
    </joint>
    <link name="caster_link">
      <pose>-0.23 0 0.065 0 0 0</pose>
      <inertial>
        <mass>0.1</mass>
        <inertia>
          <ixx>0.00017</ixx>
          <ixy>0.0</ixy>
          <ixz>0.0</ixz>
          <iyy>0.00017</iyy>
          <iyz>0.0</iyz>
          <izz>0.00017</izz>
        </inertia>
      </inertial>
      <collision name="collision">
        <geometry>
          <sphere>
            <radius>0.065</radius>
          </sphere>
        </geometry>
        <surface>
          <friction>
            <ode>
              <mu>0.01</mu>
              <mu2>0.01</mu2>
            </ode>
          </friction>
          <contact>
            <ode>
              <kp>50000</kp>
              <kd>1</kd>
            </ode>
          </contact>
        </surface>        
      </collision>
      <visual name="visual">
        <geometry>
          <sphere>
            <radius>0.065</radius>
          </sphere>
        </geometry>
        <material>
          <script>
            <uri>file://media/materials/scripts/gazebo.material</uri>
            <name>Gazebo/Gray</name>
          </script>
        </material>
      </visual>
    </link>

    <joint name='front_sensor_joint' type='fixed'>
      <parent>body_link</parent>
      <child>front_laser_link</child>
      <pose>0 0 0 0 0 0</pose>
      <axis>
        <use_parent_model_frame>true</use_parent_model_frame>
        <xyz>0 1 0</xyz>
      </axis>
    </joint>
    <link name="front_laser_link">
      <pose>0.138 0 0.06 0 0 0</pose>
      <inertial>
        <mass>0.1</mass>
        <inertia>
          <ixx>0.000015</ixx>
          <ixy>0.0</ixy>
          <ixz>0.0</ixz>
          <iyy>0.000015</iyy>
          <iyz>0.0</iyz>
          <izz>0.000015</izz>
        </inertia>
      </inertial>
      <collision name="collision">
        <geometry>
          <cylinder>
            <radius>0.033</radius>
            <length>0.01</length>
          </cylinder>
        </geometry>
      </collision>
      <visual name="visual">
        <geometry>
          <cylinder>
            <radius>0.033</radius>
            <length>0.01</length>
          </cylinder>
        </geometry>
        <material>
          <script>
            <uri>file://media/materials/scripts/gazebo.material</uri>
            <name>Gazebo/Blue</name>
          </script>
        </material>
      </visual>

      <sensor type="ray" name="front_laser">
        <pose>0 0 0 0 0 0</pose>
        <visualize>true</visualize>
        <update_rate>10</update_rate>
        <ray>
          <scan>
            <horizontal>
              <samples>400</samples>
              <resolution>1</resolution>
              <min_angle>-3.1415</min_angle>
              <max_angle>3.1415</max_angle>
            </horizontal>
          </scan>
          <range>
            <min>0.1</min>
            <max>20.0</max>
            <resolution>0.01</resolution>
          </range>
          <noise>
            <type>gaussian</type>
            <mean>0.0</mean>
            <stddev>0.01</stddev>
          </noise>
        </ray>
        <plugin name="gazebo_lidar_plugin" filename="libgazebo_ros_ray_sensor.so">
          <ros>
            <argument>~/out:=/device/front_laser/scan</argument>
          </ros>
          <output_type>sensor_msgs/LaserScan</output_type>
        </plugin>
      </sensor>
    </link>

    <joint name='sonar_0_joint' type='fixed'>
      <parent>body_link</parent>
      <child>sonar_0_link</child>
    </joint>
    <link name="sonar_0_link">
      <pose>-0.19 0.06 0.08 0 0 2.8</pose>
      <inertial>
        <mass>0.1</mass>
        <inertia>
          <ixx>0.000015</ixx>
          <ixy>0.0</ixy>
          <ixz>0.0</ixz>
          <iyy>0.000015</iyy>
          <iyz>0.0</iyz>
          <izz>0.000015</izz>
        </inertia>
      </inertial>
      <visual name="visual">
        <pose>0 0 0 0 1.5707 0</pose>
        <geometry>
          <cylinder>
            <radius>0.015</radius>
            <length>0.01</length>
          </cylinder>
        </geometry>
        <material>
          <script>
            <uri>file://media/materials/scripts/gazebo.material</uri>
            <name>Gazebo/Blue</name>
          </script>
        </material>
      </visual>

      <sensor type="ray" name="TeraRanger">
        <pose>0 0 0 0 0 0</pose>
        <visualize>true</visualize>
        <update_rate>10</update_rate>
        <ray>
          <scan>
              <horizontal>
                <samples>3</samples>
                <resolution>1</resolution> 
                <min_angle>-0.12</min_angle>
                <max_angle>0.12</max_angle>
              </horizontal>
              <vertical>
                <samples>3</samples>
                <resolution>1</resolution> 
                <min_angle>-0.05</min_angle>
                <max_angle>0.05</max_angle> 
              </vertical>
          </scan>
          <range>
              <min>0.20</min>
              <max>1</max>
              <resolution>0.01</resolution>
          </range>
        </ray>
      </sensor>
    </link>

    <joint name='sonar_1_joint' type='fixed'>
      <parent>body_link</parent>
      <child>sonar_1_link</child>
    </joint>
    <link name="sonar_1_link">
      <pose>-0.19 -0.06 0.08 0 0 -2.8</pose>
      <inertial>
        <mass>0.1</mass>
        <inertia>
          <ixx>0.000015</ixx>
          <ixy>0.0</ixy>
          <ixz>0.0</ixz>
          <iyy>0.000015</iyy>
          <iyz>0.0</iyz>
          <izz>0.000015</izz>
        </inertia>
      </inertial>
      <visual name="visual">
        <pose>0 0 0 0 1.5707 0</pose>
        <geometry>
          <cylinder>
            <radius>0.015</radius>
            <length>0.01</length>
          </cylinder>
        </geometry>
        <material>
          <script>
            <uri>file://media/materials/scripts/gazebo.material</uri>
            <name>Gazebo/Blue</name>
          </script>
        </material>
      </visual>

      <sensor type="ray" name="TeraRanger">
        <pose>0 0 0 0 0 0</pose>
        <visualize>true</visualize>
        <update_rate>10</update_rate>
        <ray>
          <scan>
              <horizontal>
                <samples>3</samples>
                <resolution>1</resolution> 
                <min_angle>-0.12</min_angle>
                <max_angle>0.12</max_angle>
              </horizontal>
              <vertical>
                <samples>3</samples>
                <resolution>1</resolution> 
                <min_angle>-0.05</min_angle>
                <max_angle>0.05</max_angle> 
              </vertical>
          </scan>
          <range>
              <min>0.20</min>
              <max>1</max>
              <resolution>0.01</resolution>
          </range>
        </ray>
      </sensor>
    </link>

    <joint name='frame_joint' type='fixed'>
      <parent>body_link</parent>
      <child>frame_link</child>
    </joint>

    <link name="frame_link">
      <pose>0 0 0.150 0 0 0</pose>
      <inertial>
        <pose>-0.04 0 0 0 0 0</pose>
        <mass>1.0</mass>
        <inertia>
          <ixx>0.0077</ixx>
          <ixy>0.0</ixy>
          <ixz>0.0</ixz>
          <iyy>0.0059</iyy>
          <iyz>0.0</iyz>
          <izz>0.011</izz>
        </inertia>
      </inertial>
      
      <visual name="visual_base">
        <pose>-0.04 0 0 0 0 0</pose>
        <geometry>
          <box>
            <size>0.24 0.28 0.12</size>
          </box>
        </geometry>
        <material>
          <script>
            <uri>file://media/materials/scripts/gazebo.material</uri>
            <name>Gazebo/Grey</name>
          </script>
        </material>
      </visual>
    </link>

    <plugin name="mavros_move_plugin" filename="libmavros_move_plugin.so">
    </plugin>
  </model>
</sdf>


        <!-- <plugin filename="libgazebo_ros_range.so" name="gazebo_ros_range">
          <gaussianNoise>0.005</gaussianNoise>
          <alwaysOn>true</alwaysOn>
          <updateRate>10</updateRate>
          <topicName>/device/mavros/sensor0/range</topicName>
          <frameName>sonor_0_link</frameName>
          <radiation>ultrasound</radiation>
          <fov>0.3</fov>
        </plugin> -->
